2025-03-17 15:49:51.863 | INFO     | app:create_app:66 - Application started with environment: development
2025-03-17 15:49:59.475 | INFO     | app.routes.credentials:test:291 - Testing credential ID 1 (TestUser1) of type sftp
2025-03-17 15:49:59.476 | DEBUG    | app.routes.credentials:test:299 - SFTP connection test initiated: transfer.slicedhealth.com:22 with user testuser1
2025-03-17 15:49:59.476 | DEBUG    | app.utils.sftp_utils:connect:37 - Attempting to connect to SFTP server: transfer.slicedhealth.com:22 with username: testuser1 from local IP: 172.16.2.33
2025-03-17 15:49:59.477 | WARNING  | app.utils.sftp_utils:connect:41 - Host key checking disabled for transfer.slicedhealth.com
2025-03-17 15:49:59.477 | DEBUG    | app.utils.sftp_utils:connect:65 - Using password authentication
2025-03-17 15:49:59.497 | ERROR    | app.utils.sftp_utils:connect:83 - Connection reset by server transfer.slicedhealth.com. This could indicate a firewall blocking the connection from 172.16.2.33, incorrect port, or server rejecting the connection.
2025-03-17 15:49:59.498 | DEBUG    | app.utils.sftp_utils:connect:93 - SSH Exception details: Traceback (most recent call last):
  File "/home/ec2-user/transferwizard/.venv/lib64/python3.9/site-packages/paramiko/transport.py", line 2292, in _check_banner
    buf = self.packetizer.readline(timeout)
  File "/home/ec2-user/transferwizard/.venv/lib64/python3.9/site-packages/paramiko/packet.py", line 374, in readline
    buf += self._read_timeout(timeout)
  File "/home/ec2-user/transferwizard/.venv/lib64/python3.9/site-packages/paramiko/packet.py", line 601, in _read_timeout
    x = self.__socket.recv(128)
ConnectionResetError: [Errno 104] Connection reset by peer

During handling of the above exception, another exception occurred:

Traceback (most recent call last):
  File "/home/ec2-user/transferwizard/app/utils/sftp_utils.py", line 71, in connect
    self.connection = pysftp.Connection(**connect_kwargs)
  File "/home/ec2-user/transferwizard/.venv/lib64/python3.9/site-packages/pysftp/__init__.py", line 143, in __init__
    self._transport.connect(**self._tconnect)
  File "/home/ec2-user/transferwizard/.venv/lib64/python3.9/site-packages/paramiko/transport.py", line 1369, in connect
    self.start_client()
  File "/home/ec2-user/transferwizard/.venv/lib64/python3.9/site-packages/paramiko/transport.py", line 722, in start_client
    raise e
  File "/home/ec2-user/transferwizard/.venv/lib64/python3.9/site-packages/paramiko/transport.py", line 2113, in run
    self._check_banner()
  File "/home/ec2-user/transferwizard/.venv/lib64/python3.9/site-packages/paramiko/transport.py", line 2296, in _check_banner
    raise SSHException(
paramiko.ssh_exception.SSHException: Error reading SSH protocol banner[Errno 104] Connection reset by peer

2025-03-17 15:49:59.498 | ERROR    | app.utils.sftp_utils:test_connection:149 - SFTP connection test failed (SSH error): Error reading SSH protocol banner[Errno 104] Connection reset by peer
2025-03-17 15:49:59.498 | INFO     | app.routes.credentials:test:346 - Credential test result: False
2025-03-17 17:40:18.280 | INFO     | app.routes.credentials:test:291 - Testing credential ID 1 (TestUser1) of type sftp
2025-03-17 17:40:18.280 | DEBUG    | app.routes.credentials:test:299 - SFTP connection test initiated: transfer.slicedhealth.com:22 with user testuser1
2025-03-17 17:40:18.280 | DEBUG    | app.utils.sftp_utils:connect:37 - Attempting to connect to SFTP server: transfer.slicedhealth.com:22 with username: testuser1 from local IP: 172.16.2.33
2025-03-17 17:40:18.281 | WARNING  | app.utils.sftp_utils:connect:41 - Host key checking disabled for transfer.slicedhealth.com
2025-03-17 17:40:18.281 | DEBUG    | app.utils.sftp_utils:connect:65 - Using password authentication
2025-03-17 17:40:18.298 | ERROR    | app.utils.sftp_utils:connect:83 - Connection reset by server transfer.slicedhealth.com. This could indicate a firewall blocking the connection from 172.16.2.33, incorrect port, or server rejecting the connection.
2025-03-17 17:40:18.298 | DEBUG    | app.utils.sftp_utils:connect:93 - SSH Exception details: Traceback (most recent call last):
  File "/home/ec2-user/transferwizard/.venv/lib64/python3.9/site-packages/paramiko/transport.py", line 2292, in _check_banner
    buf = self.packetizer.readline(timeout)
  File "/home/ec2-user/transferwizard/.venv/lib64/python3.9/site-packages/paramiko/packet.py", line 374, in readline
    buf += self._read_timeout(timeout)
  File "/home/ec2-user/transferwizard/.venv/lib64/python3.9/site-packages/paramiko/packet.py", line 601, in _read_timeout
    x = self.__socket.recv(128)
ConnectionResetError: [Errno 104] Connection reset by peer

During handling of the above exception, another exception occurred:

Traceback (most recent call last):
  File "/home/ec2-user/transferwizard/app/utils/sftp_utils.py", line 71, in connect
    self.connection = pysftp.Connection(**connect_kwargs)
  File "/home/ec2-user/transferwizard/.venv/lib64/python3.9/site-packages/pysftp/__init__.py", line 143, in __init__
    self._transport.connect(**self._tconnect)
  File "/home/ec2-user/transferwizard/.venv/lib64/python3.9/site-packages/paramiko/transport.py", line 1369, in connect
    self.start_client()
  File "/home/ec2-user/transferwizard/.venv/lib64/python3.9/site-packages/paramiko/transport.py", line 722, in start_client
    raise e
  File "/home/ec2-user/transferwizard/.venv/lib64/python3.9/site-packages/paramiko/transport.py", line 2113, in run
    self._check_banner()
  File "/home/ec2-user/transferwizard/.venv/lib64/python3.9/site-packages/paramiko/transport.py", line 2296, in _check_banner
    raise SSHException(
paramiko.ssh_exception.SSHException: Error reading SSH protocol banner[Errno 104] Connection reset by peer

2025-03-17 17:40:18.299 | ERROR    | app.utils.sftp_utils:test_connection:149 - SFTP connection test failed (SSH error): Error reading SSH protocol banner[Errno 104] Connection reset by peer
2025-03-17 17:40:18.299 | INFO     | app.routes.credentials:test:346 - Credential test result: False
2025-03-17 17:41:00.850 | INFO     | app.routes.credentials:test:291 - Testing credential ID 1 (TestUser1) of type sftp
2025-03-17 17:41:00.850 | DEBUG    | app.routes.credentials:test:299 - SFTP connection test initiated: transfer.slicedhealth.com:22 with user testuser1
2025-03-17 17:41:00.851 | DEBUG    | app.utils.sftp_utils:connect:37 - Attempting to connect to SFTP server: transfer.slicedhealth.com:22 with username: testuser1 from local IP: 172.16.2.33
2025-03-17 17:41:00.851 | WARNING  | app.utils.sftp_utils:connect:41 - Host key checking disabled for transfer.slicedhealth.com
2025-03-17 17:41:00.851 | DEBUG    | app.utils.sftp_utils:connect:65 - Using password authentication
2025-03-17 17:41:00.873 | ERROR    | app.utils.sftp_utils:connect:83 - Connection reset by server transfer.slicedhealth.com. This could indicate a firewall blocking the connection from 172.16.2.33, incorrect port, or server rejecting the connection.
2025-03-17 17:41:00.873 | DEBUG    | app.utils.sftp_utils:connect:93 - SSH Exception details: Traceback (most recent call last):
  File "/home/ec2-user/transferwizard/.venv/lib64/python3.9/site-packages/paramiko/transport.py", line 2292, in _check_banner
    buf = self.packetizer.readline(timeout)
  File "/home/ec2-user/transferwizard/.venv/lib64/python3.9/site-packages/paramiko/packet.py", line 374, in readline
    buf += self._read_timeout(timeout)
  File "/home/ec2-user/transferwizard/.venv/lib64/python3.9/site-packages/paramiko/packet.py", line 601, in _read_timeout
    x = self.__socket.recv(128)
ConnectionResetError: [Errno 104] Connection reset by peer

During handling of the above exception, another exception occurred:

Traceback (most recent call last):
  File "/home/ec2-user/transferwizard/app/utils/sftp_utils.py", line 71, in connect
    self.connection = pysftp.Connection(**connect_kwargs)
  File "/home/ec2-user/transferwizard/.venv/lib64/python3.9/site-packages/pysftp/__init__.py", line 143, in __init__
    self._transport.connect(**self._tconnect)
  File "/home/ec2-user/transferwizard/.venv/lib64/python3.9/site-packages/paramiko/transport.py", line 1369, in connect
    self.start_client()
  File "/home/ec2-user/transferwizard/.venv/lib64/python3.9/site-packages/paramiko/transport.py", line 722, in start_client
    raise e
  File "/home/ec2-user/transferwizard/.venv/lib64/python3.9/site-packages/paramiko/transport.py", line 2113, in run
    self._check_banner()
  File "/home/ec2-user/transferwizard/.venv/lib64/python3.9/site-packages/paramiko/transport.py", line 2296, in _check_banner
    raise SSHException(
paramiko.ssh_exception.SSHException: Error reading SSH protocol banner[Errno 104] Connection reset by peer

2025-03-17 17:41:00.873 | ERROR    | app.utils.sftp_utils:test_connection:149 - SFTP connection test failed (SSH error): Error reading SSH protocol banner[Errno 104] Connection reset by peer
2025-03-17 17:41:00.873 | INFO     | app.routes.credentials:test:346 - Credential test result: False
